## Ошибки (Errors)

Библиотеки подпрограмм часто должны возвращать какой-то признак ошибки для вызывающего.
Как уже упоминалось ранее, множественные значения в Go могут легко возвращать подробное описание ошибки вместе с нормальным возвращением значения.
Использование данной особенности Go для возвращения детального описания ошибки является хорошим стилем.
Например, как вы увидите `os.Open` при неудаче не просто возвращает указатель на  `nil`, он также возвращает значение ошибки, описывающей что пошло не так.

В соответствии с соглашением, ошибки имеют тип `error`, простой встроенный интерфейс.

```go
type error interface {
    Error() string
}
```

Библиотека записи может реализовать данный интерфейс с богатой моделью покрытия, что позволяет не только увидеть ошибку, но и также обеспечить некий контекст.
Как уже отмечалось, наряду с обычным `*os.File` возвращением значения, `os.Open` также возвращает значение ошибки.
Если файл будет успешно открыт то значение ошибки будет `nil`, но когда есть проблема, то будет передана `os.PathError`:

```go
// PathError records an error and the operation and
// file path that caused it.
type PathError struct {
    Op string    // "open", "unlink", etc.
    Path string  // The associated file.
    Err error    // Returned by the system call.
}

func (e * PathError) Error() string {
    return e.Op + " " + e.Path + ": " + e.Err.Error()
}
```

Ошибка `Error` в `PathError` сгенерирует строку как эта:

```command
open /etc/passwx: no such file or directory
```

Такая ошибка, которая включает имя проблемного файла, операции, ошибка операционной системы и т.д., полезная, даже если напечатать далеко от вызова; это гораздо полезнее, что просто запись "файл или папка не найдены".


Если это возможно, то строка ошибки должна определять происхождение, например, при наличии префикса имен операции или пакета, который вызвал ошибку.
Например, в пакете `image` при ошибки декодирования представлена от неизвестного формата: "image: unknown format".


Вызывающие, которые заботятся о точности ошибки, могут использовать переключатель типов *type switch* или *type assertion* для того специфицирования ошибок и получения большего количества деталей. Для `PathErrors` это означает включения изучения внутренних полей `Err` для восстановления причины отказа.


```go
for try := 0; try < 2; try++ {
    file, err = os.Create(filename)
    if err == nil {
        return
    }
    if e, ok := err.(*os.PathError); ok && e.Err == syscall.ENOSPC {
        deleteTempFiles()  // Recover some space.
        continue
    }
    return
}
```

Здесь вторая проверка `if` это ещё другой тип *type assertion*.
Если это не удается, то `ok` будет *false* и значение `e` будет `nil`.
Если это удается, то `ok` будет *true*, который означает, что имеет тип `*os.PathError`, и затем когда `e`, который мы можем рассматривать для более подробной информации об ошибке.


### Паника (Panic)


Обычный способ сообщить об ошибке к абоненту, это вернуть `error`, в качестве дополнительного возвращаемого значения. Канонический метод `Read` является хорошим примером, который возвращает количество байт и `error`. Но что если ошибка невосстановимая? Иногда программа просто не может продолжать работать.

Для этого есть встроенная функция `panic`, которая создаёт ошибку во время выполнения программы, которая остановит программу (но смотрите следующий раздел).
Функция принимает один аргумент произвольного типа, часто используется строка для вывода на печать, так как программа умирает. Это также путь указать, что произошло что-то невозможное, как например выход из бесконечного цикла.


```go
// A toy implementation of cube root using Newton's method.
func CubeRoot(x float64) float64 {
    z := x/3   // Arbitrary initial value
    for i := 0; i < 1e6; i++ {
        prevz := z
        z -= (z*z*z-x) / (3*z*z)
        if veryClose(z, prevz) {
            return z
        }
    }
    // A million iterations has not converged; something is wrong.
    panic(fmt.Sprintf("CubeRoot(%g) did not converge", x))
}
```


Это всего лишь пример и в реальных библиотечных функциях следует избегать `panic`. Если проблема может быть замаскирована или работать по другому алгоритму, то это всегда лучше, чтобы программа продолжала работать, а не выключать её. Один из возможных примеров: если библиотека действительно не может это сделать, то это причина паниковать.

```go
var user = os.Getenv("USER")

func init() {
    if user == "" {
        panic("no value for $USER")
    }
}
```

### Восстановление (Recover)

Когда вызывается `panic`, в том числе не явно при наличии ошибок во время выполнения программы, к примеру когда происходит обращение к срезу за его пределами или при некорректной работы с типами, происходит немедленное прекращение работы функции и начинается раскручивание стека горутин, запуск всех отсроченных функций *defer*.
Если раскручивание достигает вершины стека, то программа умирает. Тем не менее, можно использовать встроенную функцию `recover`, чтобы восстановить контроль над горутинами и возобновить нормальное выполнение.

Вызов `recover` останавливает раскручивание и возвращает аргументы в `panic`. Поскольку только код, который работает во время раскручивания внутри отложенных функций, `recover` полезно устанавливать внутри отложенных функций.

Одно `recover` приложение выключает недопустимые горутины изнутри, то сервер без выключения других запущенных горутин.

```go
func server(workChan <-chan *Work) {
    for work := range workChan {
        go safelyDo(work)
    }
}

func safelyDo(work *Work) {
    defer func() {
        if err := recover(); err != nil {
            log.Println("work failed:", err)
        }
    }()
    do(work)
}
```

В этом примере, если будет вызвана паника в  `do(work)`, то результат будет залогирован и горутина закончит работу без препятствия выполнения для других. Там нет необходимости делать что то дополнительно при отсроченном выполнении; вызывание `recover` обрабатывает состояние полностью.


Так как `recover` всегда возвращает `nil`, если вызывалась из отложенной функции, отложенный код может вызывать библиотеку функций, которые сами используют `panic` и `recover` без сбоя.
К примеру, отложенная функция в `safelyDo` может вызвать функцию логирования до вызова `recover`, и этот код логирования будет работать не зависимо от состоянии паники.


С помощью данного шаблона восстановления , функция `do` (и все что он вызывает) может выйти из любой ситуации вызовом `panic`.
Мы можем использовать данную идею для простой обработки ошибок в сложной программе. Давайте взглянем на идеализированную версию пакета `regexp`, которая сообщает об ошибке с помощью `panic` с типом локальной ошибки. Это определение `Error`, в методе `error` и функции `Compile`.

```go
// Error is the type of a parse error; it satisfies the error interface.
type Error string
func (e Error) Error() string {
    return string(e)
}

// error is a method of *Regexp that reports parsing errors by
// panicking with an Error.
func (regexp *Regexp) error(err string) {
    panic(Error(err))
}

// Compile returns a parsed representation of the regular expression.
func Compile(str string) (regexp *Regexp, err error) {
    regexp = new(Regexp)
    // doParse will panic if there is a parse error.
    defer func() {
        if e := recover(); e != nil {
            regexp = nil    // Clear return value.
            err = e.(Error) // Will re-panic if not a parse error.
        }
    }()
    return regexp.doParse(str), nil
}
```

Если происходит паника в `doParse`, то блок восстановления будет устанавливать значение `nil` отложенная функция может модифицировать имя возвращаемых значений.
Затем он проверяет, значение `err`, синтаксическая ошибка имеет локальный тип `Error`. Если этого не произойдет, то это приведет к ошибке во время выполнения и будет раскручивать стек.
Эта проверка означает что если происходит что-то неожиданное, как выход за пределы индексирования, код будет прерван даже при использовании `panic` и `recover` для обработки ошибок.


При наличии обработчика ошибок, метод `error` (потому его метод связан с типом, это хорошо, так как он имеет то же имя что встроенный тип `error`) позволяет легко сообщить о наличии синтаксической ошибки, не беспокоясь о разматывания стек вручную:

```go
if pos == 0 {
    re.error("'*' illegal at start of expression")
}
```

Данный шаблон полезный в рамках только одного пакета. Превращение `Parse`  внутреннего вызова `panic` в значение `error`, что позволяет на выставлять `panics` для клиента. Это хорошее правило, чтобы ему следовать.


Данный подход, меняет идиому паник на значение паники если произошла ошибка.
Тем не менее, как оригинальная, так и новые сбои будут представлены в отчёте сбоев, поэтому основная причина этой проблемы не будет видна.
Если Вы хотите увидеть только оригинальные значения, Вам необходимо немного больше кода для фильтрации неожиданных проблем и повторно паниковать с оригинальной ошибкой.
